[32m2024-12-20 03:32:33 +0000[0m - dagster - [34mDEBUG[0m - __ASSET_JOB - 53a6adc2-4016-45c8-b261-61dcad4a763e - 1420213 - LOGS_CAPTURED - Started capturing logs in process (pid: 1420213).
[32m2024-12-20 03:32:33 +0000[0m - dagster - [34mDEBUG[0m - __ASSET_JOB - 53a6adc2-4016-45c8-b261-61dcad4a763e - 1420213 - raw_buoy_data - STEP_START - Started execution of step "raw_buoy_data".
[32m2024-12-20 03:32:33 +0000[0m - dagster - [34mINFO[0m - __ASSET_JOB - 53a6adc2-4016-45c8-b261-61dcad4a763e - raw_buoy_data - Starting wave data collection
[32m2024-12-20 03:32:33 +0000[0m - dagster - [34mERROR[0m - [31m__ASSET_JOB - 53a6adc2-4016-45c8-b261-61dcad4a763e - raw_buoy_data - Error processing wave data: no running event loop[0m
[32m2024-12-20 03:32:33 +0000[0m - dagster - [34mERROR[0m - [31m__ASSET_JOB - 53a6adc2-4016-45c8-b261-61dcad4a763e - 1420213 - raw_buoy_data - STEP_FAILURE - Execution of step "raw_buoy_data" failed.

dagster._core.errors.DagsterExecutionStepExecutionError: Error occurred while executing op "raw_buoy_data"::

UnboundLocalError: cannot access local variable 'processor' where it is not associated with a value

Stack Trace:
  File "/usr/local/google/home/lacectk/current_odyssey/venv/lib/python3.11/site-packages/dagster/_core/execution/plan/utils.py", line 54, in op_execution_error_boundary
    yield
  File "/usr/local/google/home/lacectk/current_odyssey/venv/lib/python3.11/site-packages/dagster/_utils/__init__.py", line 490, in iterate_with_context
    next_output = next(iterator)
                  ^^^^^^^^^^^^^^
  File "/usr/local/google/home/lacectk/current_odyssey/venv/lib/python3.11/site-packages/dagster/_core/execution/plan/compute_generator.py", line 140, in _coerce_op_compute_fn_to_iterator
    result = invoke_compute_fn(
             ^^^^^^^^^^^^^^^^^^
  File "/usr/local/google/home/lacectk/current_odyssey/venv/lib/python3.11/site-packages/dagster/_core/execution/plan/compute_generator.py", line 128, in invoke_compute_fn
    return fn(context, **args_to_pass) if context_arg_provided else fn(**args_to_pass)
           ^^^^^^^^^^^^^^^^^^^^^^^^^^^
  File "/usr/local/google/home/lacectk/current_odyssey/src/backend/dagster_break_analytics/assets/buoy_data_dag.py", line 95, in raw_buoy_data
    processor.close()
    ^^^^^^^^^

The above exception occurred during handling of the following exception:
dagster._core.errors.DagsterUnknownResourceError: Unknown resource `email_notification`. Specify `email_notification` as a required resource on the compute / config function that accessed it.

Stack Trace:
  File "/usr/local/google/home/lacectk/current_odyssey/src/backend/dagster_break_analytics/assets/buoy_data_dag.py", line 88, in raw_buoy_data
    email_client = context.resources.email_notification.get_client()
                   ^^^^^^^^^^^^^^^^^^^^^^^^^^^^^^^^^^^^
  File "/usr/local/google/home/lacectk/current_odyssey/venv/lib/python3.11/site-packages/dagster/_core/definitions/scoped_resources_builder.py", line 29, in __getattr__
    raise DagsterUnknownResourceError(name)

The above exception occurred during handling of the following exception:
RuntimeError: no running event loop

Stack Trace:
  File "/usr/local/google/home/lacectk/current_odyssey/src/backend/dagster_break_analytics/assets/buoy_data_dag.py", line 23, in raw_buoy_data
    stations = StationsFetcher()
               ^^^^^^^^^^^^^^^^^
  File "/usr/local/google/home/lacectk/current_odyssey/src/backend/stations/stations.py", line 18, in __init__
    self.fetcher = NDBCDataFetcher()
                   ^^^^^^^^^^^^^^^^^
  File "/usr/local/google/home/lacectk/current_odyssey/src/backend/stations/ndbc_stations_data.py", line 10, in __init__
    self._session = aiohttp.ClientSession()
                    ^^^^^^^^^^^^^^^^^^^^^^^
  File "/usr/local/google/home/lacectk/current_odyssey/venv/lib/python3.11/site-packages/aiohttp/client.py", line 310, in __init__
    loop = loop or asyncio.get_running_loop()
                   ^^^^^^^^^^^^^^^^^^^^^^^^^^
[0m
