[32m2024-12-21 04:46:26 +0000[0m - dagster - [34mDEBUG[0m - __ASSET_JOB - 5fd57393-205e-497f-855f-9db6e93ba85b - 2447215 - LOGS_CAPTURED - Started capturing logs in process (pid: 2447215).
[32m2024-12-21 04:46:26 +0000[0m - dagster - [34mDEBUG[0m - __ASSET_JOB - 5fd57393-205e-497f-855f-9db6e93ba85b - 2447215 - raw_buoy_data - STEP_START - Started execution of step "raw_buoy_data".
[32m2024-12-21 04:46:26 +0000[0m - dagster - [34mINFO[0m - __ASSET_JOB - 5fd57393-205e-497f-855f-9db6e93ba85b - raw_buoy_data - Starting wave data collection
WARNING:  database "stations" has a collation version mismatch
DETAIL:  The database was created using collation version 2.38, but the operating system provides version 2.39.
HINT:  Rebuild all objects in this database that use the default collation and run ALTER DATABASE stations REFRESH COLLATION VERSION, or build PostgreSQL with the right library version.
[32m2024-12-21 04:46:26 +0000[0m - dagster - [34mINFO[0m - __ASSET_JOB - 5fd57393-205e-497f-855f-9db6e93ba85b - raw_buoy_data - Found 918 stations to process
/usr/local/google/home/lacectk/current_odyssey/src/backend/dagster_break_analytics/assets/buoy_data_dag.py:34: RuntimeWarning: coroutine 'LocalizedWaveProcessor.process_data' was never awaited
  processor.process_data()
RuntimeWarning: Enable tracemalloc to get the object allocation traceback
[32m2024-12-21 04:46:26 +0000[0m - dagster - [34mINFO[0m - __ASSET_JOB - 5fd57393-205e-497f-855f-9db6e93ba85b - raw_buoy_data - Wave data fetched successfully
[32m2024-12-21 04:46:26 +0000[0m - dagster - [34mINFO[0m - __ASSET_JOB - 5fd57393-205e-497f-855f-9db6e93ba85b - raw_buoy_data - Processed 0 records from 0 stations
[32m2024-12-21 04:46:26 +0000[0m - dagster - [34mDEBUG[0m - __ASSET_JOB - 5fd57393-205e-497f-855f-9db6e93ba85b - 2447215 - raw_buoy_data - STEP_OUTPUT - Yielded output "result" of type "DataFrame". (Type check passed).
[32m2024-12-21 04:46:26 +0000[0m - dagster - [34mINFO[0m - __ASSET_JOB - 5fd57393-205e-497f-855f-9db6e93ba85b - raw_buoy_data - Writing 0 rows to wave_data_raw_buoy_data
[32m2024-12-21 04:46:26 +0000[0m - dagster - [34mERROR[0m - [31m__ASSET_JOB - 5fd57393-205e-497f-855f-9db6e93ba85b - raw_buoy_data - Error writing to PostgreSQL: 'PostgresIOManager' object has no attribute '_engine'[0m
[32m2024-12-21 04:46:26 +0000[0m - dagster - [34mERROR[0m - [31m__ASSET_JOB - 5fd57393-205e-497f-855f-9db6e93ba85b - 2447215 - raw_buoy_data - STEP_FAILURE - Execution of step "raw_buoy_data" failed.

dagster._core.errors.DagsterExecutionHandleOutputError: Error occurred while handling output "result" of step "raw_buoy_data"::

AttributeError: 'PostgresIOManager' object has no attribute '_engine'

Stack Trace:
  File "/usr/local/google/home/lacectk/current_odyssey/venv/lib/python3.11/site-packages/dagster/_core/execution/plan/utils.py", line 54, in op_execution_error_boundary
    yield
  File "/usr/local/google/home/lacectk/current_odyssey/venv/lib/python3.11/site-packages/dagster/_utils/__init__.py", line 490, in iterate_with_context
    next_output = next(iterator)
                  ^^^^^^^^^^^^^^
  File "/usr/local/google/home/lacectk/current_odyssey/venv/lib/python3.11/site-packages/dagster/_core/execution/plan/execute_step.py", line 749, in _gen_fn
    gen_output = output_manager.handle_output(output_context, output.value)
                 ^^^^^^^^^^^^^^^^^^^^^^^^^^^^^^^^^^^^^^^^^^^^^^^^^^^^^^^^^^
  File "/usr/local/google/home/lacectk/current_odyssey/src/backend/dagster_break_analytics/io_managers/postgres_io_manager.py", line 59, in handle_output
    with self._engine.begin() as conn:
         ^^^^^^^^^^^^
  File "/usr/local/google/home/lacectk/current_odyssey/venv/lib/python3.11/site-packages/pydantic/main.py", line 856, in __getattr__
    raise AttributeError(f'{type(self).__name__!r} object has no attribute {item!r}')
[0m
